Workbook

Sheet Cover
A1: Academy Sports + Outdoors Valuation Model
A4: Company | B4: Academy Sports and Outdoors, Inc.
A5: Ticker | B5: ASO
A6: Currency | B6: USD in millions, except per-share data
A7: Historical Period | B7: Fiscal 2023-Fiscal 2025
A8: Forecast Period | B8: Fiscal 2026E-Fiscal 2030E
A9: Fiscal Year End | B9: Saturday closest to January 31
A10: Scenario | B10: Base Case
A11: Prepared By | B11: Jared Tyler Fontecha
A12: Model Version | B12: 1
A14: Purpose | B14: Three-statement, DCF, comparable-company, and LBO analysis of Academy Sports + Outdoors.

Sheet Sources
A1: Sources and Audit Trail
A3: Source ID | B3: Document | C3: Filing Type | D3: Fiscal Period | E3: Filing Date | F3: Local File | G3: URL | H3: Used For | I3: Notes
A4: S1 | B4: Academy Sports + Outdoors 2025 Annual Report | C4: 10-K | D4: Fiscal 2025 | E4: 46098 | F4: data/raw/academy_2025_10k.pdf | G4: https://investors.academy.com/static-files/62169eba-0019-4a9b-88d1-42e713a679f5 | H4: Company overview and historical financial statements | I4: Fiscal year ended Jan 31. 2026
A5: S2 | B5: Academy Sports + Outdoors 2025 Annual Report | C5: 10-K | D5: Fiscal 2024 | E5: 45736 | F5: data/raw/academy_2024_10k.pdf | G5: https://investors.academy.com/static-files/b6761f64-ddd4-4b84-baf8-8c1274e4e5f9 | H5: Fiscal 2023 balance sheet | I5: Fiscal year ended February 1, 2025
A6: S3 | B6: Academy Sports + Outdoors Q1 Fiscal 2026 Earnings Release | C6: Earnings Release | D6: Q1 Fiscal 2026 | E6: 46182 | F6: data/raw/academy_q1_2026_earnings_release.pdf | G6: https://investors.academy.com/node/11946/pdf | H6: Fiscal 2026 forecast assumptions and management guidance | I6: Page 2: updated sales growth, comparable sales, gross margin, tax rate, net income and capital expenditure guidance
A7: S4 | B7: U.S. Treasury | C7: Gov Market Data | D7: N/A | E7: 46260 | F7: N/A | G7: https://home.treasury.gov/resource-center/data-chart-center/interest-rates/TextView?field_tdr_date_value=2026&type=daily_treasury_yield_curve | H7: The 4.66% risk-free rate used in WACC | I7: 10-year U.S. Treasury yield of 4.66% as of August 26, 2026
A8: S5 | B8: Damodaran/NYU | C8: Academic Market Data | D8: N/A | E8: 46235 | F8: N/A | G8: https://pages.stern.nyu.edu/~adamodar/ | H8: The 4.28% equity risk premium used in WACC | I8: U.S. implied equity risk premium of 4.28% as of August 1, 2026
A9: S6 | B9: Google Finance | C9: Market Data | D9: N/A | E9: 46260 | F9: N/A | G9: https://www.google.com/finance/quote/ASO:NASDAQ | H9: ASO’s 1.06 beta, $43.54 share price and 62.020 million shares | I9: ASO market-data snapshot as of August 26, 2026; values change over time
A10: S7 | B10: DICK'S Sporting Goods FY2025 Results | C10: Earnings Release | D10: Fiscal 2025 | E10: 46093 | F10: N/A | G10: https://investors.dicks.com/news/news-details/2026/DICKS-Sporting-Goods-Inc--Reports-Fourth-Quarter-and-Full-Year-2025-Results-Delivers-Record-Setting-Fourth-Quarter-Sales-for-the-DICKS-Business/default.aspx | H10: Debt, cash, revenue, EBITDA and net income for comparable-company analysis | I10: Fiscal year ended January 31, 2026; includes Foot Locker following its 2025 acquisition
A11: S8 | B11: Boot Barn Holdings FY2026 Annual Report | C11: 10-K | D11: Fiscal 2026 | E11: 46156 | F11: N/A | G11: https://www.sec.gov/Archives/edgar/data/1610250/000110465926061346/boot-20260328x10k.htm | H11: Debt, cash, revenue, EBITDA and net income for comparable-company analysis | I11: Fiscal year ended March 28, 2026; EBITDA calculated as operating income plus depreciation and amortization
A12: S9 | B12: Sportsman's Warehouse FY2025 Results | C12: Earnings Release | D12: Fiscal 2025 | E12: 46112 | F12: N/A | G12: https://investors.sportsmans.com/news-releases/news-release-details/sportsmans-warehouse-holdings-inc-announces-fourth-quarter-19 | H12: Debt, cash, revenue, EBITDA and net income for comparable-company analysis | I12: Fiscal year ended January 31, 2026; unadjusted EBITDA calculated as operating income plus D&A; P/E is not meaningful due to net loss
A13: S10 | B13: Tractor Supply Company FY2025 Annual Report | C13: 10-K | D13: Fiscal 2025 | E13: 46072 | F13: N/A | G13: https://www.sec.gov/Archives/edgar/data/916365/000091636526000014/tsco-20251227.htm | H13: Debt, cash, revenue, EBITDA and net income for comparable-company analysis | I13: Fiscal year ended December 27, 2025; EBITDA calculated as operating income plus depreciation and amortization

Sheet Historicals
A1: Academy Sports + Outdoors Historical Financials
A3: Income Statement ($ in millions)
B4: 2023A | C4: 2024A | D4: 2025A
A5: Net Sales | B5: 6159.291 | C5: 5933.45 | D5: 6053.414
A6: Cost of Goods Sold | B6: 4049.08 | C6: 3921.99 | D6: 3947.801
A7: Gross Profit | B7: =B5-B6 -> 2110.211 | C7: =C5-C6 -> 2011.46 | D7: =D5-D6 -> 2105.613
A8: Selling, General and Administrative Expenses | B8: 1432.356 | C8: 1472.821 | D8: 1593.429
A9: Operating Income | B9: =B7-B8 -> 677.855 | C9: =C7-C8 -> 538.639 | D9: =D7-D8 -> 512.184
A10: Interest Expense, Net | B10: 46.051 | C10: 36.873 | D10: 36.214
A11: Write-Off of Deferred Loan Costs | B11: 1.525 | C11: 0.449 | D11: 0
A12: Other Income, Net | B12: 32.877 | C12: 36.908 | D12: 10.087
A13: Income Before Income Taxes | B13: =B9-B10-B11+B12 -> 663.156 | C13: =C9-C10-C11+C12 -> 538.225 | D13: =D9-D10-D11+D12 -> 486.057
A14: Income Tax Expense | B14: 143.966 | C14: 119.778 | D14: 109.289
A15: Net Income | B15: =B13-B14 -> 519.19 | C15: =C13-C14 -> 418.447 | D15: =D13-D14 -> 376.768
A17: Diluted Earnings Per Share | B17: =B15/B18 -> 6.7019066 | C17: =C15/C18 -> 5.7283841 | D17: =D15/D18 -> 5.5379369
A18: Diluted Weighted Average Shares | B18: 77.469 | C18: 73.048 | D18: 68.034
A21: Balance Sheet ($ in millions)
B22: 2023A | C22: 2024A | D22: 2025A
A23: Cash and Cash Equivalents | B23: 347.92 | C23: 288.929 | D23: 330.32
A24: Accounts Receivable | B24: 19.371 | C24: 16.759 | D24: 34.755
A25: Merchandise Inventories | B25: 1194.159 | C25: 1308.84 | D25: 1503.756
A26: Prepaid Expenses and Other Current Assets | B26: 83.45 | C26: 95.621 | D26: 82.457
A27: Assets Held for Sale | B27: 0 | C27: 0 | D27: 2.957
A28: Total Current Assets | B28: =SUM(B23:B27) -> 1644.9 | C28: =SUM(C23:C27) -> 1710.149 | D28: =SUM(D23:D27) -> 1954.245
A30: Property and Equipment, Net | B30: 445.209 | C30: 525.136 | D30: 584.103
A31: Right-of-Use Assets | B31: 1111.237 | C31: 1173.075 | D31: 1234.246
A32: Trade Name | B32: 578.236 | C32: 579.007 | D32: 579.766
A33: Goodwill | B33: 861.92 | C33: 861.92 | D33: 861.92
A34: Other Noncurrent Assets | B34: 35.211 | C34: 51.676 | D34: 62.756
A35: Total Assets | B35: =B28+SUM(B30:B34) -> 4676.713 | C35: =C28+SUM(C30:C34) -> 4900.963 | D35: =D28+SUM(D30:D34) -> 5277.036
A38: Liabilities and Stockholders' Equity
B39: 2023A | C39: 2024A | D39: 2025A
A40: Accounts Payable | B40: 541.077 | C40: 612.424 | D40: 637.854
A41: Accrued Expenses and Other Current Liabilities | B41: 217.932 | C41: 230.323 | D41: 243.908
A42: Current Lease Liabilities | B42: 117.849 | C42: 115.134 | D42: 147.491
A43: Current Maturities of Long-Term Debt | B43: 3 | C43: 3 | D43: 3
A44: Total Current Liabilities | B44: =SUM(B40:B43) -> 879.858 | C44: =SUM(C40:C43) -> 960.881 | D44: =SUM(D40:D43) -> 1032.253
A46: Long-Term Debt, Net | B46: 484.551 | C46: 482.679 | D46: 480.793
A47: Long-Term Lease Liabilities | B47: 1091.294 | C47: 1185.741 | D47: 1261.167
A48: Deferred Tax Liabilities, Net | B48: 254.796 | C48: 256.815 | D48: 300.654
...

Sheet Assumptions
A1: Academy Sports + Outdoors Forecast Assumptions
H2: Historical Reference
B3: 2026E | C3: 2027E | D3: 2028E | E3: 2029E | F3: 2030E | H3: 2023A | I3: 2024A | J3: 2025A
A5: Operating Assumptions
A6: Comparable Sales Growth | B6: 0.01 | C6: 0.02 | D6: 0.02 | E6: 0.02 | F6: 0.02
A7: New Store Contribution | B7: 0.03 | C7: 0.03 | D7: 0.025 | E7: 0.025 | F7: 0.02
A8: Net Sales Growth | B8: =SUM(B6:B7) -> 0.04 | C8: =SUM(C6:C7) -> 0.05 | D8: =SUM(D6:D7) -> 0.045 | E8: =SUM(E6:E7) -> 0.045 | F8: =SUM(F6:F7) -> 0.04
A9: Gross Margin % | B9: 0.3475 | C9: 0.348 | D9: 0.349 | E9: 0.35 | F9: 0.35
A10: SG&A as % of Sales | B10: 0.261 | C10: 0.26 | D10: 0.259 | E10: 0.258 | F10: 0.258
A11: Effective Tax Rate | B11: 0.225 | C11: 0.225 | D11: 0.225 | E11: 0.225 | F11: 0.225
A14: Balance Sheet and Cash Flow Assumptions
A15: Accounts Receivable as % of Sales | B15: 0.004 | C15: 0.004 | D15: 0.004 | E15: 0.004 | F15: 0.004 | H15: =Historicals!B24/Historicals!B5 -> 0.0031450048 | I15: =Historicals!C24/Historicals!C5 -> 0.002824495 | J15: =Historicals!D24/Historicals!D5 -> 0.0057413882
A16: Inventory as % of Sales | B16: 0.245 | C16: 0.24 | D16: 0.235 | E16: 0.23 | F16: 0.23 | H16: =Historicals!B25/Historicals!B5 -> 0.1938793 | I16: =Historicals!C25/Historicals!C5 -> 0.22058667 | J16: =Historicals!D25/Historicals!D5 -> 0.24841453
A17: Prepaid Expenses as % of Sales | B17: 0.015 | C17: 0.015 | D17: 0.015 | E17: 0.015 | F17: 0.015 | H17: =Historicals!B26/Historicals!B5 -> 0.013548637 | I17: =Historicals!C26/Historicals!C5 -> 0.016115582 | J17: =Historicals!D26/Historicals!D5 -> 0.01362157
A18: Accounts Payable as % of COGS | B18: 0.16 | C18: 0.16 | D18: 0.16 | E18: 0.16 | F18: 0.16 | H18: =Historicals!B40/Historicals!B6 -> 0.13362961 | I18: =Historicals!C40/Historicals!C6 -> 0.15615134 | J18: =Historicals!D40/Historicals!D6 -> 0.16157197
A19: Accrued Expenses as % of Sales | B19: 0.04 | C19: 0.04 | D19: 0.04 | E19: 0.04 | F19: 0.04 | H19: =Historicals!B41/Historicals!B5 -> 0.035382644 | I19: =Historicals!C41/Historicals!C5 -> 0.03881772 | J19: =Historicals!D41/Historicals!D5 -> 0.040292635
A20: Capital Expenditures as % of Sales | B20: 0.035 | C20: 0.035 | D20: 0.035 | E20: 0.035 | F20: 0.035 | H20: =-Historicals!B71/Historicals!B5 -> 0.033732779 | I20: =-Historicals!C71/Historicals!C5 -> 0.033637934 | J20: =-Historicals!D71/Historicals!D5 -> 0.035131911
A21: D&A as % of Beginning PP&E | B21: 0.25 | C21: 0.25 | D21: 0.25 | E21: 0.25 | F21: 0.25 | I21: =Historicals!C63/Historicals!B30 -> 0.26520129 | J21: =Historicals!D63/Historicals!C30 -> 0.23396987
A22: Dividend Growth | B22: 0.1 | C22: 0.08 | D22: 0.07 | E22: 0.06 | F22: 0.05 | I22: =ABS(Historicals!C82)/ABS(Historicals!B82)-1 -> 0.15596297 | J22: =ABS(Historicals!D82)/ABS(Historicals!C82)-1 -> 0.10151607
A23: Share Repurchases ($ in millions) | B23: 200 | C23: 200 | D23: 200 | E23: 200 | F23: 200 | H23: =-Historicals!B81 -> 202.796 | I23: =-Historicals!C81 -> 364.912 | J23: =-Historicals!D81 -> 198.978
A24: Assets Held For Sale | B24: 0 | C24: 0 | D24: 0 | E24: 0 | F24: 0
A25: Right-of-Use Assets as % of Sales | B25: 0.205 | C25: 0.205 | D25: 0.205 | E25: 0.205 | F25: 0.205
A26: Other Noncurrent Assets as % of Sales | B26: 0.01 | C26: 0.01 | D26: 0.01 | E26: 0.01 | F26: 0.01

Sheet Operating Model
A1: Academy Sports + Outdoors Operating Model
B3: 2023A | C3: 2024A | D3: 2025A | E3: 2026E | F3: 2027E | G3: 2028E | H3: 2029E | I3: 2030E
A5: Net Sales | B5: =Historicals!B5 -> 6159.291 | C5: =Historicals!C5 -> 5933.45 | D5: =Historicals!D5 -> 6053.414 | E5: =D5*(1+Assumptions!B8) -> 6295.5506 | F5: =E5*(1+Assumptions!C8) -> 6610.3281 | G5: =F5*(1+Assumptions!D8) -> 6907.7929 | H5: =G5*(1+Assumptions!E8) -> 7218.6435 | I5: =H5*(1+Assumptions!F8) -> 7507.3893
A6: Net Sales Growth | C6: =C5/B5-1 -> -0.03666672 | D6: =D5/C5-1 -> 0.020218254 | E6: =Assumptions!B8 -> 0.04 | F6: =Assumptions!C8 -> 0.05 | G6: =Assumptions!D8 -> 0.045 | H6: =Assumptions!E8 -> 0.045 | I6: =Assumptions!F8 -> 0.04
A7: Cost of Goods Sold | B7: =Historicals!B6 -> 4049.08 | C7: =Historicals!C6 -> 3921.99 | D7: =Historicals!D6 -> 3947.801 | E7: =E5*(1-Assumptions!B9) -> 4107.8467 | F7: =F5*(1-Assumptions!C9) -> 4309.9339 | G7: =G5*(1-Assumptions!D9) -> 4496.9731 | H7: =H5*(1-Assumptions!E9) -> 4692.1183 | I7: =I5*(1-Assumptions!F9) -> 4879.803
A8: Gross Profit | B8: =Historicals!B7 -> 2110.211 | C8: =Historicals!C7 -> 2011.46 | D8: =Historicals!D7 -> 2105.613 | E8: =E5-E7 -> 2187.7038 | F8: =F5-F7 -> 2300.3942 | G8: =G5-G7 -> 2410.8197 | H8: =H5-H7 -> 2526.5252 | I8: =I5-I7 -> 2627.5862
A9: Gross Margin % | B9: =B8/B5 -> 0.34260615 | C9: =C8/C5 -> 0.33900345 | D9: =D8/D5 -> 0.34783892 | E9: =E8/E5 -> 0.3475 | F9: =F8/F5 -> 0.348 | G9: =G8/G5 -> 0.349 | H9: =H8/H5 -> 0.35 | I9: =I8/I5 -> 0.35
A10: Selling, General and Administrative Expenses | B10: =Historicals!B8 -> 1432.356 | C10: =Historicals!C8 -> 1472.821 | D10: =Historicals!D8 -> 1593.429 | E10: =E5*Assumptions!B10 -> 1643.1387 | F10: =F5*Assumptions!C10 -> 1718.6853 | G10: =G5*Assumptions!D10 -> 1789.1183 | H10: =H5*Assumptions!E10 -> 1862.41 | I10: =I5*Assumptions!F10 -> 1936.9064
A11: SG&A as % of Sales | B11: =B10/B5 -> 0.23255209 | C11: =C10/C5 -> 0.24822338 | D11: =D10/D5 -> 0.26322816 | E11: =E10/E5 -> 0.261 | F11: =F10/F5 -> 0.26 | G11: =G10/G5 -> 0.259 | H11: =H10/H5 -> 0.258 | I11: =I10/I5 -> 0.258
A12: Operating Income | B12: =Historicals!B9 -> 677.855 | C12: =Historicals!C9 -> 538.639 | D12: =Historicals!D9 -> 512.184 | E12: =E8-E10 -> 544.56512 | F12: =F8-F10 -> 581.70887 | G12: =G8-G10 -> 621.70136 | H12: =H8-H10 -> 664.1152 | I12: =I8-I10 -> 690.67981
A13: Operating Margin % | B13: =B12/B5 -> 0.11005406 | C13: =C12/C5 -> 0.090780069 | D13: =D12/D5 -> 0.084610767 | E13: =E12/E5 -> 0.0865 | F13: =F12/F5 -> 0.088 | G13: =G12/G5 -> 0.09 | H13: =H12/H5 -> 0.092 | I13: =I12/I5 -> 0.092

Sheet 3-Statement
A1: Academy Sports + Outdoors Integrated Three-Statement Model
B3: 2023A | C3: 2024A | D3: 2025A | E3: 2026E | F3: 2027E | G3: 2028E | H3: 2029E | I3: 2030E
A5: Income Statement ($ in millions)
A6: Net Sales | B6: =Historicals!B5 -> 6159.291 | C6: =Historicals!C5 -> 5933.45 | D6: =Historicals!D5 -> 6053.414 | E6: ='Operating Model'!E5 -> 6295.5506 | F6: ='Operating Model'!F5 -> 6610.3281 | G6: ='Operating Model'!G5 -> 6907.7929 | H6: ='Operating Model'!H5 -> 7218.6435 | I6: ='Operating Model'!I5 -> 7507.3893
A7: Cost of Goods Sold | B7: =Historicals!B6 -> 4049.08 | C7: =Historicals!C6 -> 3921.99 | D7: =Historicals!D6 -> 3947.801 | E7: ='Operating Model'!E7 -> 4107.8467 | F7: ='Operating Model'!F7 -> 4309.9339 | G7: ='Operating Model'!G7 -> 4496.9731 | H7: ='Operating Model'!H7 -> 4692.1183 | I7: ='Operating Model'!I7 -> 4879.803
A8: Gross Profit | B8: =Historicals!B7 -> 2110.211 | C8: =Historicals!C7 -> 2011.46 | D8: =Historicals!D7 -> 2105.613 | E8: ='Operating Model'!E8 -> 2187.7038 | F8: ='Operating Model'!F8 -> 2300.3942 | G8: ='Operating Model'!G8 -> 2410.8197 | H8: ='Operating Model'!H8 -> 2526.5252 | I8: ='Operating Model'!I8 -> 2627.5862
A9: Selling, General and Administrative Expenses | B9: =Historicals!B8 -> 1432.356 | C9: =Historicals!C8 -> 1472.821 | D9: =Historicals!D8 -> 1593.429 | E9: ='Operating Model'!E10 -> 1643.1387 | F9: ='Operating Model'!F10 -> 1718.6853 | G9: ='Operating Model'!G10 -> 1789.1183 | H9: ='Operating Model'!H10 -> 1862.41 | I9: ='Operating Model'!I10 -> 1936.9064
A10: Operating Income | B10: =Historicals!B9 -> 677.855 | C10: =Historicals!C9 -> 538.639 | D10: =Historicals!D9 -> 512.184 | E10: ='Operating Model'!E12 -> 544.56512 | F10: ='Operating Model'!F12 -> 581.70887 | G10: ='Operating Model'!G12 -> 621.70136 | H10: ='Operating Model'!H12 -> 664.1152 | I10: ='Operating Model'!I12 -> 690.67981
A11: Interest Expense, Net | B11: =Historicals!B10 -> 46.051 | C11: =Historicals!C10 -> 36.873 | D11: =Historicals!D10 -> 36.214 | E11: =AVERAGE(D44+D41,E44+E41)*($D$11/AVERAGE($C$44+$C$41,$D$44+$D$41)) -> 36.031487 | F11: =AVERAGE(E44+E41,F44+F41)*($D$11/AVERAGE($C$44+$C$41,$D$44+$D$41)) -> 35.807361 | G11: =AVERAGE(F44+F41,G44+G41)*($D$11/AVERAGE($C$44+$C$41,$D$44+$D$41)) -> 35.583234 | H11: =AVERAGE(G44+G41,H44+H41)*($D$11/AVERAGE($C$44+$C$41,$D$44+$D$41)) -> 35.359108 | I11: =AVERAGE(H44+H41,I44+I41)*($D$11/AVERAGE($C$44+$C$41,$D$44+$D$41)) -> 35.134982
A12: Write-Off of Deferred Loan Costs | B12: =Historicals!B11 -> 1.525 | C12: =Historicals!C11 -> 0.449 | D12: =Historicals!D11 -> 0 | E12: =D12 -> 0 | F12: =E12 -> 0 | G12: =F12 -> 0 | H12: =G12 -> 0 | I12: =H12 -> 0
A13: Other Income, Net | B13: =Historicals!B12 -> 32.877 | C13: =Historicals!C12 -> 36.908 | D13: =Historicals!D12 -> 10.087 | E13: =E$6*($D$13/$D$6) -> 10.49048 | F13: =F$6*($D$13/$D$6) -> 11.015004 | G13: =G$6*($D$13/$D$6) -> 11.510679 | H13: =H$6*($D$13/$D$6) -> 12.02866 | I13: =I$6*($D$13/$D$6) -> 12.509806
A14: Income Before Income Taxes | B14: =Historicals!B13 -> 663.156 | C14: =Historicals!C13 -> 538.225 | D14: =Historicals!D13 -> 486.057 | E14: =E10-E11-E12+E13 -> 519.02412 | F14: =F10-F11-F12+F13 -> 556.91652 | G14: =G10-G11-G12+G13 -> 597.6288 | H14: =H10-H11-H12+H13 -> 640.78476 | I14: =I10-I11-I12+I13 -> 668.05464
A15: Income Tax Expense | B15: =Historicals!B14 -> 143.966 | C15: =Historicals!C14 -> 119.778 | D15: =Historicals!D14 -> 109.289 | E15: =E14*Assumptions!B11 -> 116.78043 | F15: =F14*Assumptions!C11 -> 125.30622 | G15: =G14*Assumptions!D11 -> 134.46648 | H15: =H14*Assumptions!E11 -> 144.17657 | I15: =I14*Assumptions!F11 -> 150.31229
A16: Net Income | B16: =Historicals!B15 -> 519.19 | C16: =Historicals!C15 -> 418.447 | D16: =Historicals!D15 -> 376.768 | E16: =E14-E15 -> 402.24369 | F16: =F14-F15 -> 431.6103 | G16: =G14-G15 -> 463.16232 | H16: =H14-H15 -> 496.60819 | I16: =I14-I15 -> 517.74234
A19: Blance Sheet ($ in millions)
B20: 2023A | C20: 2024A | D20: 2025A | E20: 2026E | F20: 2027E | G20: 2028E | H20: 2029E | I20: 2030E
A21: Cash and Cash Equivalents | B21: =Historicals!B23 -> 347.92 | C21: =Historicals!C23 -> 288.929 | D21: =Historicals!D23 -> 330.32 | E21: =E86 -> 484.43334 | F21: =F86 -> 673.87294 | G21: =G86 -> 900.09808 | H21: =H86 -> 1162.0666 | I21: =I86 -> 1414.1186
A22: Accounts Receivable | B22: =Historicals!B24 -> 19.371 | C22: =Historicals!C24 -> 16.759 | D22: =Historicals!D24 -> 34.755 | E22: =E$6*Assumptions!B15 -> 25.182202 | F22: =F$6*Assumptions!C15 -> 26.441312 | G22: =G$6*Assumptions!D15 -> 27.631171 | H22: =H$6*Assumptions!E15 -> 28.874574 | I22: =I$6*Assumptions!F15 -> 30.029557
A23: Merchandise Inventories | B23: =Historicals!B25 -> 1194.159 | C23: =Historicals!C25 -> 1308.84 | D23: =Historicals!D25 -> 1503.756 | E23: =E$6*Assumptions!B16 -> 1542.4099 | F23: =F$6*Assumptions!C16 -> 1586.4787 | G23: =G$6*Assumptions!D16 -> 1623.3313 | H23: =H$6*Assumptions!E16 -> 1660.288 | I23: =I$6*Assumptions!F16 -> 1726.6995
A24: Prepaid Expenses and Other Current Assets | B24: =Historicals!B26 -> 83.45 | C24: =Historicals!C26 -> 95.621 | D24: =Historicals!D26 -> 82.457 | E24: =E$6*Assumptions!B17 -> 94.433258 | F24: =F$6*Assumptions!C17 -> 99.154921 | G24: =G$6*Assumptions!D17 -> 103.61689 | H24: =H$6*Assumptions!E17 -> 108.27965 | I24: =I$6*Assumptions!F17 -> 112.61084
A25: Assets Held for Sale | B25: =Historicals!B27 -> 0 | C25: =Historicals!C27 -> 0 | D25: =Historicals!D27 -> 2.957 | E25: =Assumptions!B24 -> 0 | F25: =Assumptions!C24 -> 0 | G25: =Assumptions!D24 -> 0 | H25: =Assumptions!E24 -> 0 | I25: =Assumptions!F24 -> 0
A26: Total Current Assets | B26: =Historicals!B28 -> 1644.9 | C26: =Historicals!C28 -> 1710.149 | D26: =Historicals!D28 -> 1954.245 | E26: =SUM(E21:E25) -> 2146.4587 | F26: =SUM(F21:F25) -> 2385.9479 | G26: =SUM(G21:G25) -> 2654.6775 | H26: =SUM(H21:H25) -> 2959.5089 | I26: =SUM(I21:I25) -> 3283.4585
A28: Property and Equipment, Net | B28: =Historicals!B30 -> 445.209 | C28: =Historicals!C30 -> 525.136 | D28: =Historicals!D30 -> 584.103 | E28: =D28+(E$6*Assumptions!B20)-(D28*Assumptions!B21) -> 658.42152 | F28: =E28+(F$6*Assumptions!C20)-(E28*Assumptions!C21) -> 725.17762 | G28: =F28+(G$6*Assumptions!D20)-(F28*Assumptions!D21) -> 785.65597 | H28: =G28+(H$6*Assumptions!E20)-(G28*Assumptions!E21) -> 841.8945 | I28: =H28+(I$6*Assumptions!F20)-(H28*Assumptions!F21) -> 894.1795
A29: Right-of-Use Assets | B29: =Historicals!B31 -> 1111.237 | C29: =Historicals!C31 -> 1173.075 | D29: =Historicals!D31 -> 1234.246 | E29: =E$6*Assumptions!B25 -> 1290.5879 | F29: =F$6*Assumptions!C25 -> 1355.1173 | G29: =G$6*Assumptions!D25 -> 1416.0975 | H29: =H$6*Assumptions!E25 -> 1479.8219 | I29: =I$6*Assumptions!F25 -> 1539.0148
A30: Trade Name | B30: =Historicals!B32 -> 578.236 | C30: =Historicals!C32 -> 579.007 | D30: =Historicals!D32 -> 579.766 | E30: =D30-E70 -> 580.525 | F30: =E30-F70 -> 581.284 | G30: =F30-G70 -> 582.043 | H30: =G30-H70 -> 582.802 | I30: =H30-I70 -> 583.561
A31: Goodwill | B31: =Historicals!B33 -> 861.92 | C31: =Historicals!C33 -> 861.92 | D31: =Historicals!D33 -> 861.92 | E31: =D31 -> 861.92 | F31: =E31 -> 861.92 | G31: =F31 -> 861.92 | H31: =G31 -> 861.92 | I31: =H31 -> 861.92
A32: Other Noncurrent Assets | B32: =Historicals!B34 -> 35.211 | C32: =Historicals!C34 -> 51.676 | D32: =Historicals!D34 -> 62.756 | E32: =E$6*Assumptions!B26 -> 62.955506 | F32: =F$6*Assumptions!C26 -> 66.103281 | G32: =G$6*Assumptions!D26 -> 69.077929 | H32: =H$6*Assumptions!E26 -> 72.186435 | I32: =I$6*Assumptions!F26 -> 75.073893
A33: Total Assets | B33: =Historicals!B35 -> 4676.713 | C33: =Historicals!C35 -> 4900.963 | D33: =Historicals!D35 -> 5277.036 | E33: =E26+SUM(E28:E32) -> 5600.8686 | F33: =F26+SUM(F28:F32) -> 5975.5501 | G33: =G26+SUM(G28:G32) -> 6369.4719 | H33: =H26+SUM(H28:H32) -> 6798.1337 | I33: =I26+SUM(I28:I32) -> 7237.2077
A36: Liabilities and Stockholders' Equity
A38: Accounts Payable | B38: =Historicals!B40 -> 541.077 | C38: =Historicals!C40 -> 612.424 | D38: =Historicals!D40 -> 637.854 | E38: =E$7*Assumptions!B18 -> 657.25548 | F38: =F$7*Assumptions!C18 -> 689.58943 | G38: =G$7*Assumptions!D18 -> 719.5157 | H38: =H$7*Assumptions!E18 -> 750.73893 | I38: =I$7*Assumptions!F18 -> 780.76848
A39: Accured Expenses and Other Current Liabilities | B39: =Historicals!B41 -> 217.932 | C39: =Historicals!C41 -> 230.323 | D39: =Historicals!D41 -> 243.908 | E39: =E$6*Assumptions!B19 -> 251.82202 | F39: =F$6*Assumptions!C19 -> 264.41312 | G39: =G$6*Assumptions!D19 -> 276.31171 | H39: =H$6*Assumptions!E19 -> 288.74574 | I39: =I$6*Assumptions!F19 -> 300.29557
A40: Current Lease Liabilities | B40: =Historicals!B42 -> 117.849 | C40: =Historicals!C42 -> 115.134 | D40: =Historicals!D42 -> 147.491 | E40: =E29*($D40/$D29) -> 154.22379 | F40: =F29*($D40/$D29) -> 161.93498 | G40: =G29*($D40/$D29) -> 169.22205 | H40: =H29*($D40/$D29) -> 176.83704 | I40: =I29*($D40/$D29) -> 183.91053
A41: Current Maturities of Long-Term Debt | B41: =Historicals!B43 -> 3 | C41: =Historicals!C43 -> 3 | D41: =Historicals!D43 -> 3 | E41: =D41 -> 3 | F41: =E41 -> 3 | G41: =F41 -> 3 | H41: =G41 -> 3 | I41: =H41 -> 3
A42: Total Current Liabilities | B42: =Historicals!B44 -> 879.858 | C42: =Historicals!C44 -> 960.881 | D42: =Historicals!D44 -> 1032.253 | E42: =SUM(E38:E41) -> 1066.3013 | F42: =SUM(F38:F41) -> 1118.9375 | G42: =SUM(G38:G41) -> 1168.0495 | H42: =SUM(H38:H41) -> 1219.3217 | I42: =SUM(I38:I41) -> 1267.9746
A44: Long-Term Debt, Net | B44: =Historicals!B46 -> 484.551 | C44: =Historicals!C46 -> 482.679 | D44: =Historicals!D46 -> 480.793 | E44: =D44-E41 -> 477.793 | F44: =E44-F41 -> 474.793 | G44: =F44-G41 -> 471.793 | H44: =G44-H41 -> 468.793 | I44: =H44-I41 -> 465.793
A45: Long-Term Lease Liabilities | B45: =Historicals!B47 -> 1091.294 | C45: =Historicals!C47 -> 1185.741 | D45: =Historicals!D47 -> 1261.167 | E45: =E29*($D45/$D29) -> 1318.7378 | F45: =F29*($D45/$D29) -> 1384.6747 | G45: =G29*($D45/$D29) -> 1446.985 | H45: =H29*($D45/$D29) -> 1512.0994 | I45: =I29*($D45/$D29) -> 1572.5833
A46: Deferred Tax Liabilities, Net | B46: =Historicals!B48 -> 254.796 | C46: =Historicals!C48 -> 256.815 | D46: =Historicals!D48 -> 300.654 | E46: =E28*($D46/$D28) -> 338.9078 | F46: =F28*($D46/$D28) -> 373.26902 | G46: =G28*($D46/$D28) -> 404.3989 | H46: =H28*($D46/$D28) -> 433.34643 | I46: =I28*($D46/$D28) -> 460.25897
A47: Other Long-Term Liabilities | B47: =Historicals!B49 -> 11.564 | C47: =Historicals!C49 -> 10.812 | D47: =Historicals!D49 -> 30.792 | E47: =E$6*($D47/$D$6) -> 32.02368 | F47: =F$6*($D47/$D$6) -> 33.624864 | G47: =G$6*($D47/$D$6) -> 35.137983 | H47: =H$6*($D47/$D$6) -> 36.719192 | I47: =I$6*($D47/$D$6) -> 38.18796
A48: Total Liabilities | B48: =Historicals!B50 -> 2722.063 | C48: =Historicals!C50 -> 2896.928 | D48: =Historicals!D50 -> 3105.659 | E48: =SUM(E42,E44:E47) -> 3233.7635 | F48: =SUM(F42,F44:F47) -> 3385.2991 | G48: =SUM(G42,G44:G47) -> 3526.3644 | H48: =SUM(H42,H44:H47) -> 3670.2797 | I48: =SUM(I42,I44:I47) -> 3804.7978
A50: Common Stock | B50: =Historicals!B52 -> 0.743 | C50: =Historicals!C52 -> 0.683 | D50: =Historicals!D52 -> 0.649 | E50: =D50 -> 0.649 | F50: =E50 -> 0.649 | G50: =F50 -> 0.649 | H50: =G50 -> 0.649 | I50: =H50 -> 0.649
...

Sheet DCF
A1: Academy Sports + Outdoors Discounted Cash Flow Valuation
E3: 2026E | F3: 2027E | G3: 2028E | H3: 2029E | I3: 2030E
A5: Unlevered Free Cash Flow ($ in millions) | K5: WACC Calculation | M5: Source
A6: Operating Income (EBIT) | E6: ='3-Statement'!E10 -> 544.56512 | F6: ='3-Statement'!F10 -> 581.70887 | G6: ='3-Statement'!G10 -> 621.70136 | H6: ='3-Statement'!H10 -> 664.1152 | I6: ='3-Statement'!I10 -> 690.67981 | K6: Risk-Free Rate | L6: 0.0466 | M6: S4
A7: Tax Rate | E7: =Assumptions!B11 -> 0.225 | F7: =Assumptions!C11 -> 0.225 | G7: =Assumptions!D11 -> 0.225 | H7: =Assumptions!E11 -> 0.225 | I7: =Assumptions!F11 -> 0.225 | K7: Equity Risk Premium | L7: 0.0428 | M7: S5
A8: NOPAT | E8: =E6*(1-E7) -> 422.03797 | F8: =F6*(1-F7) -> 450.82438 | G8: =G6*(1-G7) -> 481.81855 | H8: =H6*(1-H7) -> 514.68928 | I8: =I6*(1-I7) -> 535.27686 | K8: Levered Beta | L8: 1.06 | M8: S6
A9: Depreciation and Amortization | E9: ='3-Statement'!E61 -> 146.02575 | F9: ='3-Statement'!F61 -> 164.60538 | G9: ='3-Statement'!G61 -> 181.29441 | H9: ='3-Statement'!H61 -> 196.41399 | I9: ='3-Statement'!I61 -> 210.47362 | K9: Cost of Equity | L9: =L6+L7*L8 -> 0.091968
A10: Capital Expenditures | E10: =-'3-Statement'!E69 -> 220.34427 | F10: =-'3-Statement'!F69 -> 231.36148 | G10: =-'3-Statement'!G69 -> 241.77275 | H10: =-'3-Statement'!H69 -> 252.65252 | I10: =-'3-Statement'!I69 -> 262.75862 | K10: Pre-Tax Cost of Debt | L10: ='3-Statement'!D11/AVERAGE('3-Statement'!C44+'3-Statement'!C41,'3-Statement'!D44+'3-Statement'!D41) -> 0.074708707
A11: Change in Net Working Capital | E11: =SUM('3-Statement'!E22:E25)-SUM('3-Statement'!E38:E39)-(SUM('3-Statement'!D22:D25)-SUM('3-Statement'!D38:D39)) -> 10.784847 | F11: =SUM('3-Statement'!F22:F25)-SUM('3-Statement'!F38:F39)-(SUM('3-Statement'!E22:E25)-SUM('3-Statement'!E38:E39)) -> 5.1245782 | G11: =SUM('3-Statement'!G22:G25)-SUM('3-Statement'!G38:G39)-(SUM('3-Statement'!F22:F25)-SUM('3-Statement'!F38:F39)) -> 0.67954173 | H11: =SUM('3-Statement'!H22:H25)-SUM('3-Statement'!H38:H39)-(SUM('3-Statement'!G22:G25)-SUM('3-Statement'!G38:G39)) -> -0.79439618 | I11: =SUM('3-Statement'!I22:I25)-SUM('3-Statement'!I38:I39)-(SUM('3-Statement'!H22:H25)-SUM('3-Statement'!H38:H39)) -> 30.318303 | K11: Tax Rate | L11: =Assumptions!B11 -> 0.225
A12: Unlevered Free Cash Flow | E12: =E8+E9-E10-E11 -> 336.9346 | F12: =F8+F9-F10-F11 -> 378.94369 | G12: =G8+G9-G10-G11 -> 420.66067 | H12: =H8+H9-H10-H11 -> 459.24515 | I12: =I8+I9-I10-I11 -> 452.67355 | K12: After-Tax Cost of Debt | L12: =L10*(1-L11) -> 0.057899248
K13: Share Price | L13: 43.54 | M13: S6
A14: Discount Period | E14: 1 | F14: =E14+1 -> 2 | G14: =F14+1 -> 3 | H14: =G14+1 -> 4 | I14: =H14+1 -> 5 | K14: Diluted Shares Outstanding | L14: 62.02 | M14: S6
A15: Discount Factor | E15: =1/(1+$L$20)^E14 -> 0.92013956 | F15: =1/(1+$L$20)^F14 -> 0.84665682 | G15: =1/(1+$L$20)^G14 -> 0.77904243 | H15: =1/(1+$L$20)^H14 -> 0.71682776 | I15: =1/(1+$L$20)^I14 -> 0.65958159 | K15: Market Value of Equity | L15: =L13*L14 -> 2700.3508
A16: Present Value of UFCF | E16: =E12*E15 -> 310.02686 | F16: =F12*F15 -> 320.83526 | G16: =G12*G15 -> 327.71251 | H16: =H12*H15 -> 329.19967 | I16: =I12*I15 -> 298.57514 | K16: Debt | L16: ='3-Statement'!D44+'3-Statement'!D41 -> 483.793
K17: Total Capital | L17: =SUM(L15:L16) -> 3184.1438
A18: Terminal Value | K18: Equity Weight | L18: =L15/L17 -> 0.84806182
A19: Terminal Growth Rate | E19: 0.025 | K19: Debt Weight | L19: =L16/L17 -> 0.15193818
A20: Terminal Value | E20: =I12*(1+E19)/($L$20-E19) -> 7508.949 | K20: WACC | L20: =L9*L18+L12*L19 -> 0.086791656
A21: Present Value of Terminal Value | E21: =E20*I15 -> 4952.7645
A23: Enterprise Value | E23: =SUM(E16:I16)+E21 -> 6539.1139 | K23: DCF Sensitivity Analysis
A24: Less: Debt | E24: ='3-Statement'!D44+'3-Statement'!D41 -> 483.793 | K24: =$E$28 -> 102.961 | L24: 0.077 | M24: 0.082 | N24: 0.087 | O24: 0.092 | P24: 0.097
A25: Add: Cash | E25: ='3-Statement'!D21 -> 330.32 | K25: 0.015 | L25: 106.26848 | M25: 98.004637 | N25: 90.89028 | O25: 84.70146 | P25: 79.268846
A26: Equity Value | E26: =E23-E24+E25 -> 6385.6409 | K26: 0.02 | L26: 113.94376 | M26: 104.41449 | N26: 96.309015 | O26: 89.330699 | P26: 83.259943
A27: Diluted Shares Outstanding | E27: =$L$14 -> 62.02 | K27: 0.025 | L27: 123.09505 | M27: 111.94887 | N27: 102.60174 | O27: 94.650869 | P27: 87.805359
A28: Implied Share Price | E28: =E26/E27 -> 102.961 | K28: 0.03 | L28: 134.19342 | M28: 120.93218 | N28: 109.99845 | O28: 100.82913 | P28: 93.029196
K29: 0.035 | L29: 147.93427 | M29: 131.82682 | N29: 118.81761 | O29: 108.0913 | P29: 99.095586

Sheet Comps
A1: Academy Sports + Outdoors Comparable Companies Analysis
A3: Company | B3: Ticker | C3: Share Price | D3: Equity Value ($ in millions) | E3: Debt ($ in millions) | F3: Cash ($ in millions) | G3: Enterprise Value ($ in millions) | H3: Revenue ($ in millions) | I3: EBITDA ($ in millions) | J3: Net Income ($ in millions) | K3: EV / Revenue | L3: EV / EBITDA | M3: P / E
A4: Academy Sports + Outdoors | B4: ASO | C4: 43.54 | D4: 2700.351 | E4: ='3-Statement'!D41+'3-Statement'!D44 -> 483.793 | F4: ='3-Statement'!D21 -> 330.32 | G4: =D4+E4-F4 -> 2853.824 | H4: ='3-Statement'!D6 -> 6053.414 | I4: ='3-Statement'!D10+'3-Statement'!D61 -> 635.05 | J4: ='3-Statement'!D16 -> 376.768 | K4: =G4/H4 -> 0.47144041 | L4: =G4/I4 -> 4.4938572 | M4: =D4/J4 -> 7.1671453
A5: Dick's Sporting Goods | B5: DKS | C5: 129.66 | D5: 11600 | E5: 1905.299 | F5: 1353.226 | G5: =D5+E5-F5 -> 12152.073 | H5: 17215.12 | I5: 1584.539 | J5: 849.239 | K5: =G5/H5 -> 0.70589534 | L5: =G5/I5 -> 7.6691536 | M5: =D5/J5 -> 13.659288
A6: Boot Barn | B6: BOOT | C6: 159.72 | D6: 4870 | E6: 0 | F6: 141.036 | G6: =D6+E6-F6 -> 4728.964 | H6: 2253.859 | I6: 377.799 | J6: 225.88 | K6: =G6/H6 -> 2.0981632 | L6: =G6/I6 -> 12.517143 | M6: =D6/J6 -> 21.56012
A7: Sportsman's Warehouse | B7: SPWH | C7: 1.16 | D7: 45.26 | E7: 91.665 | F7: 1.659 | G7: =D7+E7-F7 -> 135.266 | H7: 1209.182 | I7: 1.74 | J7: -50.061 | K7: =G7/H7 -> 0.11186571 | L7: =G7/I7 -> 77.73908 | M7: N/M
A8: Tractor Supply Company | B8: TSCO | C8: 35.01 | D8: 18366.771 | E8: 1764.974 | F8: 194.109 | G8: =D8+E8-F8 -> 19937.636 | H8: 15524.046 | I8: 1961.4 | J8: 1096.087 | K8: =G8/H8 -> 1.2843067 | L8: =G8/I8 -> 10.165003 | M8: =D8/J8 -> 16.756673
A9: Median | K9: =MEDIAN(K4:K8) -> 0.70589534 | L9: =MEDIAN(L4:L8) -> 10.165003 | M9: =MEDIAN(M4:M8) -> 15.20798
A10: Mean | K10: =AVERAGE(K4:K8) -> 0.93433427 | L10: =AVERAGE(L4:L8) -> 22.516847 | M10: =AVERAGE(M4:M8) -> 14.785807
A12: Academy Implied Valuation
A13: Method | B13: Selected Multiple | C13: Academy Metric | D13: Implied Enterprise Value | E13: Implied Equity Value | F13: Diluted Shares | G13: Implied Share Price
A14: EV / Revenue | B14: =K9 -> 0.70589534 | C14: =H4 -> 6053.414 | D14: =B14*C14 -> 4273.0767 | E14: =D14-$E$4+$F$4 -> 4119.6037 | F14: =$D$4/$C$4 -> 62.020005 | G14: =E14/F14 -> 66.42379
A15: EV / EBITDA | B15: =L9 -> 10.165003 | C15: =I4 -> 635.05 | D15: =B15*C15 -> 6455.2849 | E15: =D15-$E$4+$F$4 -> 6301.8119 | F15: =$D$4/$C$4 -> 62.020005 | G15: =E15/F15 -> 101.60934
A16: P / E | B16: =M9 -> 15.20798 | C16: =J4 -> 376.768 | D16: ="" | E16: =B16*C16 -> 5729.8803 | F16: =$D$4/$C$4 -> 62.020005 | G16: =E16/F16 -> 92.387615
A18: Low Implied Share Price | B18: =MIN(G14:G16) -> 66.42379
A19: Average Implied Share Price | B19: =AVERAGE(G14:G16) -> 86.806916
A20: High Implied Share Price | B20: =MAX(G14:G16) -> 101.60934
A21: Current Share Price | B21: =C4 -> 43.54
A22: Implied Upside / (Downside) | B22: =B19/B21-1 -> 0.99372796

Sheet LBO
A1: Academy Sports + Outdoors Leveraged Buyout Analysis
A3: Transaction Assumptions
A4: Entry Share Price | B4: =Comps!C4*(1+$E$4) -> 52.248 | D4: Acquisition Premium | E4: 0.2
A5: Diluted Shares Outstanding | B5: =Comps!F14 -> 62.020005 | D5: Minimum Cash | E5: 100
A6: Purchase Equity Value | B6: =B4*B5 -> 3240.4212
A7: Existing Debt | B7: =Comps!E4 -> 483.793
A8: Transaction Fees | B8: =B6*E8 -> 64.808424 | D8: Transaction Fee % | E8: 0.02
A9: Total Uses | B9: =SUM(B6:B8) -> 3789.0226
A11: Sources
A12: Entry EBITDA | B12: =Comps!I4 -> 635.05
A13: Entry Debt / EBITDA | B13: 4.5
A14: New Debt | B14: =B12*B13 -> 2857.725
A15: Sponsor Equity | B15: =B9-B14 -> 931.29762
A16: Total Sources | B16: =SUM(B14:B15) -> 3789.0226
A17: Sources / Uses Check | B17: =B16-B9 -> 0
H19: Notes:
A20: Operating Forecast ($ in millions) | B20: 2026E | C20: 2027E | D20: 2028E | E20: 2029E | F20: 2030E
A21: Revenue | B21: ='3-Statement'!E6 -> 6295.5506 | C21: ='3-Statement'!F6 -> 6610.3281 | D21: ='3-Statement'!G6 -> 6907.7929 | E21: ='3-Statement'!H6 -> 7218.6435 | F21: ='3-Statement'!I6 -> 7507.3893
A22: EBITDA | B22: ='3-Statement'!E10+'3-Statement'!E61 -> 690.59087 | C22: ='3-Statement'!F10+'3-Statement'!F61 -> 746.31425 | D22: ='3-Statement'!G10+'3-Statement'!G61 -> 802.99576 | E22: ='3-Statement'!H10+'3-Statement'!H61 -> 860.5292 | F22: ='3-Statement'!I10+'3-Statement'!I61 -> 901.15344
A23: EBITDA Margin | B23: =B22/B21 -> 0.10969507 | C23: =C22/C21 -> 0.11290124 | D23: =D22/D21 -> 0.11624491 | E23: =E22/E21 -> 0.11920927 | F23: =F22/F21 -> 0.12003553
A24: CapEx | B24: ='3-Statement'!E69 -> -220.34427 | C24: ='3-Statement'!F69 -> -231.36148 | D24: ='3-Statement'!G69 -> -241.77275 | E24: ='3-Statement'!H69 -> -252.65252 | F24: ='3-Statement'!I69 -> -262.75862
A25: Cash Taxes | B25: =-MAX(0,('3-Statement'!E10+B32-'3-Statement'!E12+'3-Statement'!E13)*Assumptions!B11) -> -76.663401 | C25: =-MAX(0,('3-Statement'!F10+C32-'3-Statement'!F12+'3-Statement'!F13)*Assumptions!C11) -> -87.931777 | D25: =-MAX(0,('3-Statement'!G10+D32-'3-Statement'!G12+'3-Statement'!G13)*Assumptions!D11) -> -100.75378 | E25: =-MAX(0,('3-Statement'!H10+E32-'3-Statement'!H12+'3-Statement'!H13)*Assumptions!E11) -> -115.04348 | F25: =-MAX(0,('3-Statement'!I10+F32-'3-Statement'!I12+'3-Statement'!I13)*Assumptions!F11) -> -126.67707 | H25: Accounts Receivable + Inventory + Prepaids − Accounts Payable − Accrued Expenses
A26: Change in Net Working Capital | B26: =('3-Statement'!D22+'3-Statement'!D23+'3-Statement'!D24-'3-Statement'!D38-'3-Statement'!D39)-('3-Statement'!E22+'3-Statement'!E23+'3-Statement'!E24-'3-Statement'!E38-'3-Statement'!E39) -> -13.741847 | C26: =('3-Statement'!E22+'3-Statement'!E23+'3-Statement'!E24-'3-Statement'!E38-'3-Statement'!E39)-('3-Statement'!F22+'3-Statement'!F23+'3-Statement'!F24-'3-Statement'!F38-'3-Statement'!F39) -> -5.1245782 | D26: =('3-Statement'!F22+'3-Statement'!F23+'3-Statement'!F24-'3-Statement'!F38-'3-Statement'!F39)-('3-Statement'!G22+'3-Statement'!G23+'3-Statement'!G24-'3-Statement'!G38-'3-Statement'!G39) -> -0.67954173 | E26: =('3-Statement'!G22+'3-Statement'!G23+'3-Statement'!G24-'3-Statement'!G38-'3-Statement'!G39)-('3-Statement'!H22+'3-Statement'!H23+'3-Statement'!H24-'3-Statement'!H38-'3-Statement'!H39) -> 0.79439618 | F26: =('3-Statement'!H22+'3-Statement'!H23+'3-Statement'!H24-'3-Statement'!H38-'3-Statement'!H39)-('3-Statement'!I22+'3-Statement'!I23+'3-Statement'!I24-'3-Statement'!I38-'3-Statement'!I39) -> -30.318303
A27: Cash Available Before Interest | B27: =B22+B24+B25+B26 -> 379.84136 | C27: =C22+C24+C25+C26 -> 421.89641 | D27: =D22+D24+D25+D26 -> 459.78969 | E27: =E22+E24+E25+E26 -> 493.62759 | F27: =F22+F24+F25+F26 -> 481.39944
H28: LBO interest expense is calculated using the new acquisition debt balance, not the existing 3-Statement debt structure.
A29: Debt Schedule
A30: Beginning Debt | B30: =$B$14 -> 2857.725 | C30: =B35 -> 2692.213 | D30: =C35 -> 2472.2326 | E30: =D35 -> 2197.8603 | F30: =E35 -> 1869.0723
A31: Interest Rate | B31: 0.075 | C31: 0.075 | D31: 0.075 | E31: 0.075 | F31: 0.075
A32: Cash Interest | B32: =-B30*B31 -> -214.32937 | C32: =-C30*C31 -> -201.91598 | D32: =-D30*D31 -> -185.41744 | E32: =-E30*E31 -> -164.83953 | F32: =-F30*F31 -> -140.18042
A33: Cash Available After Interest | B33: =B27+B32 -> 165.51198 | C33: =C27+C32 -> 219.98044 | D33: =D27+D32 -> 274.37224 | E33: =E27+E32 -> 328.78807 | F33: =F27+F32 -> 341.21902
A34: Debt Paydown | B34: =-MIN(MAX(B33,0),B30) -> -165.51198 | C34: =-MIN(MAX(C33,0),C30) -> -219.98044 | D34: =-MIN(MAX(D33,0),D30) -> -274.37224 | E34: =-MIN(MAX(E33,0),E30) -> -328.78807 | F34: =-MIN(MAX(F33,0),F30) -> -341.21902
A35: Ending Debt | B35: =B30+B34 -> 2692.213 | C35: =C30+C34 -> 2472.2326 | D35: =D30+D34 -> 2197.8603 | E35: =E30+E34 -> 1869.0723 | F35: =F30+F34 -> 1527.8533
A38: Exit Analysis
A39: Exit Year | B39: 5
A40: Exit EBITDA | B40: =F22 -> 901.15344
A41: Exit EV / EBITDA | B41: 4.5
A42: Exit Enterprise Value | B42: =B40*B41 -> 4055.1905
A43: Less: Ending Debt | B43: =-F35 -> -1527.8533
A44: Add: Exit Cash | B44: =$E$5 -> 100
A45: Exit Equity Value | B45: =SUM(B42:B44) -> 2627.3372
...

Sheet Checks
A1: Model Checks
A2: Check name: | B2: Raw Check Value: | C2: Status:
A3: 3-Statement Balance Sheet Check | B3: {=MAX(ABS('3-Statement'!E56:I56))} -> 0 | C3: =IF(B3<0.001,"OK","ERROR") -> OK
A4: 3-Statement Cash Flow Check | B4: {=MAX(ABS('3-Statement'!E87:I87))} -> 0 | C4: =IF(B4<0.001,"OK","ERROR") -> OK
A5: LBO Sources / Uses Check | B5: =ABS(LBO!B17) -> 0 | C5: =IF(B5<0.001,"OK","ERROR") -> OK
A6: LBO Ending Debt Check | B6: =IF(MIN(LBO!B35:F35)>=0,0,1) -> 0 | C6: =IF(B6=0,"OK","ERROR") -> OK
A7: LBO Sponsor Equity Check | B7: =IF(LBO!B15>0,0,1) -> 0 | C7: =IF(B7=0,"OK","ERROR") -> OK
A8: LBO Base Case IRR Check | B8: =ABS(LBO!D63-LBO!B52) -> 0 | C8: =IF(B8<0.001,"OK","ERROR") -> OK
A9: Overall Model Status | B9: =IF(COUNTIF(C3:C8,"ERROR")=0,"MODEL OK","CHECK MODEL") -> MODEL OK
